Workbook

Sheet ipk3.1
A1: IPK III/1: IKHTISAR STATISTIK TENAGA KERJA KABUPATEN PASER
A2: PADA TANGGAL : 1 AGUSTUS 2025 s/d 31 AGUSTUS 2025
A4: I.PENCARI KERJA | B4: KELOMPOK UMUR | L4: JUMLAH
B5: 15-19 | D5: 20-29 | F5: 30-44 | H5: 45-54 | J5: 55+
B6: L | C6: P | D6: L | E6: P | F6: L | G6: P | H6: L | I6: P | J6: L | K6: P | L6: L | M6: P | N6: L+P
A7: 1. Pencari kerja yang belum ditempatkan pada bulan yang lalu | B7: 2726 | C7: 944 | D7: 3866 | E7: 1869 | F7: 421 | G7: 27 | H7: 30 | I7: 6 | J7: 0 | K7: 0 | L7: =B7+D7+F7+H7+J7 -> 7043 | M7: =C7+E7+G7+I7+K7 -> 2846 | N7: =L7+M7 -> 9889
A8: 2. Pencari kerja yang terdaftar pada bulan ini | B8: 9 | C8: 5 | D8: 39 | E8: 10 | F8: 8 | G8: 2 | H8: 0 | I8: 0 | J8: 0 | K8: 0 | L8: =J8+B8+D8+F8+H8 -> 56 | M8: =K8+C8+E8+G8+I8 -> 17 | N8: =L8+M8 -> 73
A9: A. JUMLAH (1+2) | B9: =B7+B8 -> 2735 | C9: =C7+C8 -> 949 | D9: =D7+D8 -> 3905 | E9: =E7+E8 -> 1879 | F9: =F7+F8 -> 429 | G9: =G7+G8 -> 29 | H9: =H7+H8 -> 30 | I9: =I7+I8 -> 6 | ... K9: =K7+K8 -> 0 | L9: =J9+B9+D9+F9+H9 -> 7099 | M9: =K9+C9+E9+G9+I9 -> 2863 | N9: =L9+M9 -> 9962
A10: 3. Pencari kerja yang ditempatkan pada bulan ini | B10: 0 | C10: 0 | D10: 0 | E10: 0 | F10: 0 | G10: 0 | H10: 0 | I10: 0 | J10: 0 | K10: 0 | L10: =J10+B10+D10+F10+H10 -> 0 | M10: =K10+C10+E10+G10+I10 -> 0 | N10: =L10+M10 -> 0
A11: 4. Pencari kerja yang dihapuskan pada bulan ini | B11: 0 | C11: 0 | D11: 0 | E11: 0 | F11: 0 | G11: 0 | H11: 0 | I11: 0 | J11: 0 | K11: 0 | L11: =J11+B11+D11+F11+H11 -> 0 | M11: =K11+C11+E11+G11+I11 -> 0 | N11: =L11+M11 -> 0
A12: B. JUMLAH (3+4) | B12: =B10+B11 -> 0 | C12: =C10+C11 -> 0 | D12: =D10+D11 -> 0 | E12: =E10+E11 -> 0 | F12: =F10+F11 -> 0 | G12: =G10+G11 -> 0 | H12: =H10+H11 -> 0 | I12: =I10+I11 -> 0 | ... M12: =M10+M11 -> 0 | N12: =L12+M12 -> 0
A13: 5. Pencari kerja yang belum ditempatkan pada akhir bulan ini (A-B) | B13: =B9-B12 -> 2735 | C13: =C9-C12 -> 949 | D13: =D9-D12 -> 3905 | E13: =E9-E12 -> 1879 | F13: =F9-F12 -> 429 | G13: =G9-G12 -> 29 | H13: =H9-H12 -> 30 | I13: =I9-I12 -> 6 | ... M13: =M9-M12 -> 2863 | N13: =L13+M13 -> 9962
A14: II. LOWONGAN | B14: L | C14: W | D14: L+W
A15: 1 | B15: 2 | C15: 3 | D15: 4
A16: 1. Lowongan yang belum dipenuhi pada akhir bulan lalu | B16: 485 | C16: 17 | D16: =B16+C16 -> 502
A17: 2. Lowongan yang terdaftar bulan ini | B17: 0 | C17: 0 | D17: =B17+C17 -> 0
A18: C. JUMLAH (1+2) | B18: =B16+B17 -> 485 | C18: =C16+C17 -> 17 | D18: =D16+D17 -> 502
A19: 3. Lowongan yang dipenuhi bulan ini | B19: =L10 -> 0 | C19: =M10 -> 0 | D19: =B19+C19 -> 0
A20: 4. Lowongan yang dihapuskan bulan ini | B20: 0 | C20: 0 | D20: =B20+C20 -> 0
A21: D. JUMLAH (3+4) | B21: =B19+B20 -> 0 | C21: =C19+C20 -> 0 | D21: =D19+D20 -> 0
A22: 5. Lowongan yang belum dipenuhi akhir bulan ini (C-D) | B22: =B18-B21 -> 485 | C22: =C18-C21 -> 17 | D22: =D18-D21 -> 502

Sheet ipk3.2
A1: IPK III/2: PENCARI KERJA YANG TERDAFTAR, DITEMPATKAN DAN DIHAPUSKAN DI
A2: KABUPATEN PASER MENURUT JENIS PENDIDIKAN
A3: ='ipk3.1'!A2 -> PADA TANGGAL : 1 AGUSTUS 2025 s/d 31 AGUSTUS 2025
A5: Kode | B5: Jenis Pendidikan | C5: Sisa akhir bulan lalu | E5: Pendaftaran bulan ini | G5: Penempatan bulan ini | I5: Penghapusan bulan ini | K5: Sisa akhir bulan ini
C6: L | D6: W | E6: L | F6: W | G6: L | H6: W | I6: L | J6: W | K6: L | L6: W
A7: 1 | C7: 2 | D7: 3 | E7: 4 | F7: 5 | G7: 6 | H7: 7 | I7: 8 | J7: 9 | K7: 10 | L7: 11
A8: 1000 | B8: SEKOLAH DASAR
A9: 1101 | B9: TIDAK TAMAT SD | C9: 87 | D9: 7 | E9: 0 | F9: 0 | G9: 0 | H9: 0 | I9: 0 | J9: 0 | K9: =C9+E9-G9-I9 -> 87 | L9: =D9+F9-H9-J9 -> 7
A10: 1102 | B10: TAMAT SD | C10: 89 | D10: 0 | E10: 0 | F10: 0 | G10: 0 | H10: 0 | I10: 0 | J10: 0 | K10: =C10+E10-G10-I10 -> 89 | L10: =D10+F10-H10-J10 -> 0
A11: 1103 | B11: SETINGKAT SD | C11: 0 | D11: 0 | E11: 0 | F11: 0 | G11: 0 | H11: 0 | I11: 0 | J11: 0 | K11: =C11+E11-G11-I11 -> 0 | L11: =D11+F11-H11-J11 -> 0
A12: 1199 | B12: SD - TAK TERDEFINISI | C12: 0 | D12: 0 | E12: 0 | F12: 0 | G12: 0 | H12: 0 | I12: 0 | J12: 0 | K12: =C12+E12-G12-I12 -> 0 | L12: =D12+F12-H12-J12 -> 0
A13: 2000 | B13: PENDIDIKAN MENENGAH PERTAMA
A14: 2101 | B14: SEKOLAH MENENGAH PERTAMA | C14: 194 | D14: 52 | E14: 1 | F14: 0 | G14: 0 | H14: 0 | I14: 0 | J14: 0 | K14: =C14+E14-G14-I14 -> 195 | L14: =D14+F14-H14-J14 -> 52
A15: 2102 | B15: MADRASAH DINIYAH SANAWIYAH | C15: 58 | D15: 8 | E15: 0 | F15: 0 | G15: 0 | H15: 0 | I15: 0 | J15: 0 | K15: =C15+E15-G15-I15 -> 58 | L15: =D15+F15-H15-J15 -> 8
A16: 2103 | B16: SLTP LAINNYA | C16: 66 | D16: 12 | E16: 0 | F16: 0 | G16: 0 | H16: 0 | I16: 0 | J16: 0 | K16: =C16+E16-G16-I16 -> 66 | L16: =D16+F16-H16-J16 -> 12
A17: 2104 | B17: SLTP KEJURUAN | C17: 0 | D17: 0 | E17: 0 | F17: 0 | G17: 0 | H17: 0 | I17: 0 | J17: 0 | K17: =C17+E17-G17-I17 -> 0 | L17: =D17+F17-H17-J17 -> 0
A18: 2199 | B18: SLTP - TAK TERDEFINISI | C18: 0 | D18: 0 | E18: 0 | F18: 0 | G18: 0 | H18: 0 | I18: 0 | J18: 0 | K18: =C18+E18-G18-I18 -> 0 | L18: =D18+F18-H18-J18 -> 0
A19: 3000 | B19: PENDIDIKAN MENENGAH ATAS
A20: 3101 | B20: TEKNIK BANGUNAN | C20: 194 | D20: 18 | E20: 0 | F20: 0 | G20: 0 | H20: 0 | I20: 0 | J20: 0 | K20: =C20+E20-G20-I20 -> 194 | L20: =D20+F20-H20-J20 -> 18
A21: 3102 | B21: TEKNIK PLUMBING DAN SANITASI | C21: 0 | D21: 0 | E21: 0 | F21: 0 | G21: 0 | H21: 0 | I21: 0 | J21: 0 | K21: =C21+E21-G21-I21 -> 0 | L21: =D21+F21-H21-J21 -> 0
A22: 3103 | B22: TEKNIK SURVEI DAN PEMETAAN | C22: 4 | D22: 0 | E22: 0 | F22: 0 | G22: 0 | H22: 0 | I22: 0 | J22: 0 | K22: =C22+E22-G22-I22 -> 4 | L22: =D22+F22-H22-J22 -> 0
A23: 3104 | B23: TEKNIK KETENAGALISTRIKAN | C23: 310 | D23: 6 | E23: 3 | F23: 0 | G23: 0 | H23: 0 | I23: 0 | J23: 0 | K23: =C23+E23-G23-I23 -> 313 | L23: =D23+F23-H23-J23 -> 6
A24: 3105 | B24: TEKNIK PENDINGINAN DAN TATA UDARA | C24: 27 | D24: 4 | E24: 0 | F24: 0 | G24: 0 | H24: 0 | I24: 0 | J24: 0 | K24: =C24+E24-G24-I24 -> 27 | L24: =D24+F24-H24-J24 -> 4
A25: 3106 | B25: TEKNIK MESIN | C25: 173 | D25: 3 | E25: 0 | F25: 0 | G25: 0 | H25: 0 | I25: 0 | J25: 0 | K25: =C25+E25-G25-I25 -> 173 | L25: =D25+F25-H25-J25 -> 3
A26: 3107 | B26: TEKNIK OTOMOTIF | C26: 744 | D26: 14 | E26: 10 | F26: 0 | G26: 0 | H26: 0 | I26: 0 | J26: 0 | K26: =C26+E26-G26-I26 -> 754 | L26: =D26+F26-H26-J26 -> 14
A27: 3108 | B27: TEKNOLOGI PESAWAT UDARA | C27: 2 | D27: 0 | E27: 0 | F27: 0 | G27: 0 | H27: 0 | I27: 0 | J27: 0 | K27: =C27+E27-G27-I27 -> 2 | L27: =D27+F27-H27-J27 -> 0
A28: 3109 | B28: TEKNIK PERKAPALAN | C28: 3 | D28: 0 | E28: 0 | F28: 0 | G28: 0 | H28: 0 | I28: 0 | J28: 0 | K28: =C28+E28-G28-I28 -> 3 | L28: =D28+F28-H28-J28 -> 0
A29: 3110 | B29: TEKNOLOGI TEKSTIL | C29: 0 | D29: 1 | E29: 0 | F29: 0 | G29: 0 | H29: 0 | I29: 0 | J29: 0 | K29: =C29+E29-G29-I29 -> 0 | L29: =D29+F29-H29-J29 -> 1
A30: 3111 | B30: TEKNIK GRAFIKA | C30: 0 | D30: 0 | E30: 0 | F30: 0 | G30: 0 | H30: 0 | I30: 0 | J30: 0 | K30: =C30+E30-G30-I30 -> 0 | L30: =D30+F30-H30-J30 -> 0
A31: 3112 | B31: GEOLOGI PERTAMBANGAN | C31: 27 | D31: 3 | E31: 0 | F31: 0 | G31: 0 | H31: 0 | I31: 0 | J31: 0 | K31: =C31+E31-G31-I31 -> 27 | L31: =D31+F31-H31-J31 -> 3
... A63: 3802 | B63: MADRASAH DINIYAH ALIYAH | C63: 520 | D63: 249 | E63: 4 | F63: 2 | G63: 0 | H63: 0 | I63: 0 | J63: 0 | K63: =C63+E63-G63-I63 -> 524 | L63: =D63+F63-H63-J63 -> 251
A64: 4000 | B64: DIPLOMA I / AKTA I
A65: 4101 | B65: PENDIDIKAN | C65: 0 | D65: 0 | E65: 0 | F65: 0 | G65: 0 | H65: 0 | I65: 0 | J65: 0 | K65: =C65+E65-G65-I65 -> 0 | L65: =D65+F65-H65-J65 -> 0
A66: 4102 | B66: PENDIDIKAN LUAR SEKOLAH | C66: 0 | D66: 0 | E66: 0 | F66: 0 | G66: 0 | H66: 0 | I66: 0 | J66: 0 | K66: =C66+E66-G66-I66 -> 0 | L66: =D66+F66-H66-J66 -> 0
A67: 4103 | B67: PENDIDIKAN KESEJAHTERAAN SOSIAL | C67: 0 | D67: 0 | E67: 0 | F67: 0 | G67: 0 | H67: 0 | I67: 0 | J67: 0 | K67: =C67+E67-G67-I67 -> 0 | L67: =D67+F67-H67-J67 -> 0
A68: 4104 | B68: PSIKOLOGI | C68: 0 | D68: 0 | E68: 0 | F68: 0 | G68: 0 | H68: 0 | I68: 0 | J68: 0 | K68: =C68+E68-G68-I68 -> 0 | L68: =D68+F68-H68-J68 -> 0
A69: 4105 | B69: ILMU PENGETAHUAN SOSIAL | C69: 0 | D69: 0 | E69: 0 | F69: 0 | G69: 0 | H69: 0 | I69: 0 | J69: 0 | K69: =C69+E69-G69-I69 -> 0 | L69: =D69+F69-H69-J69 -> 0
A70: 4106 | B70: PENDIDIKAN MORAL PANCASILA | C70: 0 | D70: 0 | E70: 0 | F70: 0 | G70: 0 | H70: 0 | I70: 0 | J70: 0 | K70: =C70+E70-G70-I70 -> 0 | L70: =D70+F70-H70-J70 -> 0
A71: 4107 | B71: ADMINISTRASI KEUANGAN | C71: 0 | D71: 0 | E71: 0 | F71: 0 | G71: 0 | H71: 0 | I71: 0 | J71: 0 | K71: =C71+E71-G71-I71 -> 0 | L71: =D71+F71-H71-J71 -> 0
A72: 4108 | B72: ANTROPOLOGI | C72: 0 | D72: 0 | E72: 0 | F72: 0 | G72: 0 | H72: 0 | I72: 0 | J72: 0 | K72: =C72+E72-G72-I72 -> 0 | L72: =D72+F72-H72-J72 -> 0
...

Sheet ipk3.3
A1: IPK III/3: PENCARI KERJA YANG TERDAFTAR, DITEMPATKAN DAN DIHAPUSKAN DI
A2: KABUPATEN PASER TIMUR MENURUT GOLONGAN JABATAN
A3: ='ipk3.2'!A3 -> PADA TANGGAL : 1 AGUSTUS 2025 s/d 31 AGUSTUS 2025
A5: Kode | B5: Jenis Golongan Pokok Jabatan | C5: Sisa akhir bulan lalu | E5: Pendaftaran bulan ini | G5: Penempatan bulan ini | I5: Penghapuskan bulan ini | K5: Sisa akhir bulan ini
C6: L | D6: W | E6: L | F6: W | G6: L | H6: W | I6: L | J6: W | K6: L | L6: W
A7: 1 | C7: 2 | D7: 3 | E7: 4 | F7: 5 | G7: 6 | H7: 7 | I7: 8 | J7: 9 | K7: 10 | L7: 11
A8: 0 | B8: ANGGOTA ANGKATAN BERSENJATA (KECUALI KEPOLISIAN)
A9: 110 | B9: ANGGOTA ANGKATAN BERSENJATA | C9: 0 | D9: 0 | E9: 0 | F9: 0 | G9: 0 | H9: 0 | I9: 0 | J9: 0 | K9: =C9+E9-G9-I9 -> 0 | L9: =D9+F9-H9-J9 -> 0
A10: 1 | B10: ANGGOTA BADAN LEGISLATIF, PEJABAT TINGGI PEMERINTAH
A11: 1110 | B11: ANGGOTA BADAN LEGISLATIF | C11: 0 | D11: 0 | E11: 0 | F11: 0 | G11: 0 | H11: 0 | I11: 0 | J11: 0 | K11: =C11+E11-G11-I11 -> 0 | L11: =D11+F11-H11-J11 -> 0
A12: 1120 | B12: PEJABAT TINGGI PEMERINTAH | C12: 4 | D12: 2 | E12: 0 | F12: 0 | G12: 0 | H12: 0 | I12: 0 | J12: 0 | K12: =C12+E12-G12-I12 -> 4 | L12: =D12+F12-H12-J12 -> 2
A13: 1130 | B13: KEPALA DESA DAN LURAH | C13: 0 | D13: 0 | E13: 0 | F13: 0 | G13: 0 | H13: 0 | I13: 0 | J13: 0 | K13: =C13+E13-G13-I13 -> 0 | L13: =D13+F13-H13-J13 -> 0
A14: 1141 | B14: PEMIMPIN ORGANISASI PARTAI POLITIK | C14: 0 | D14: 0 | E14: 0 | F14: 0 | G14: 0 | H14: 0 | I14: 0 | J14: 0 | K14: =C14+E14-G14-I14 -> 0 | L14: =D14+F14-H14-J14 -> 0
A15: 1142 | B15: PIMPINAN ORGANISASI PENGUSAHA, PEKERJA DAN ORGANISASI YANG BERKAITAN DENGAN KEPENTINGAN DARI ORGANISASI EKONOMI | C15: 1 | D15: 0 | E15: 0 | F15: 0 | G15: 0 | H15: 0 | I15: 0 | J15: 0 | K15: =C15+E15-G15-I15 -> 1 | L15: =D15+F15-H15-J15 -> 0
A16: 1143 | B16: PIMPINAN ORGANISASI KEMANUSIAAN DAN ORGANISASI KHUSUS | C16: 0 | D16: 0 | E16: 0 | F16: 0 | G16: 0 | H16: 0 | I16: 0 | J16: 0 | K16: =C16+E16-G16-I16 -> 0 | L16: =D16+F16-H16-J16 -> 0
A17: 1210 | B17: DIREKTUR DAN KEPALA EKSEKUTIF | C17: 0 | D17: 0 | E17: 0 | F17: 0 | G17: 0 | H17: 0 | I17: 0 | J17: 0 | K17: =C17+E17-G17-I17 -> 0 | L17: =D17+F17-H17-J17 -> 0
A18: 1221 | B18: MANAJER PRODUKSI DAN OPERASI DALAM BIDANG PERTANIAN PERBURUAN DAN PERIKANAN | C18: 1 | D18: 0 | E18: 0 | F18: 0 | G18: 0 | H18: 0 | I18: 0 | J18: 0 | K18: =C18+E18-G18-I18 -> 1 | L18: =D18+F18-H18-J18 -> 0
A19: 1223 | B19: MANAJER PRODUKSI DAN OPERASI DALAM BIDANG KONSTRUKSI | C19: 0 | D19: 0 | E19: 0 | F19: 0 | G19: 0 | H19: 0 | I19: 0 | J19: 0 | K19: =C19+E19-G19-I19 -> 0 | L19: =D19+F19-H19-J19 -> 0
A20: 1224 | B20: MANAJER PRODUKSI DAN OPERASI DOKUMEN DALAM BIDANG PERDAGANGAN BESAR DAN ECERAN | C20: 0 | D20: 0 | E20: 0 | F20: 0 | G20: 0 | H20: 0 | I20: 0 | J20: 0 | K20: =C20+E20-G20-I20 -> 0 | L20: =D20+F20-H20-J20 -> 0
A21: 1225 | B21: MANAJER PRODUKSI DAN OPERASI DALAM BIDANG HOTEL DAN RESTORAN | C21: 0 | D21: 0 | E21: 0 | F21: 0 | G21: 0 | H21: 0 | I21: 0 | J21: 0 | K21: =C21+E21-G21-I21 -> 0 | L21: =D21+F21-H21-J21 -> 0
A22: 1226 | B22: MANAJER PRODUKSI DAN OPERASI DALAM BIDANG ANGKUTAN (LAYANAN TELEKOMUNIKASI) PERGUDANGAN & KOMUNIKASI | C22: 0 | D22: 0 | E22: 0 | F22: 0 | G22: 0 | H22: 0 | I22: 0 | J22: 0 | K22: =C22+E22-G22-I22 -> 0 | L22: =D22+F22-H22-J22 -> 0
... A39: 1319 | B39: MANAJER UMUM YANG TIDAK DAPAT DIKLASIFIKASIKAN PADA SUB GOL 1311 SAMPAI DENGAN 1318 | C39: 1 | D39: 1 | E39: 0 | F39: 0 | G39: 0 | H39: 0 | I39: 0 | J39: 0 | K39: =C39+E39-G39-I39 -> 1 | L39: =D39+F39-H39-J39 -> 1
A40: 2 | B40: TENAGA PROFESIONAL
A41: 2111 | B41: PAKAR FISIKA DAN ASTRONOMI | C41: 0 | D41: 0 | E41: 0 | F41: 0 | G41: 0 | H41: 0 | I41: 0 | J41: 0 | K41: =C41+E41-G41-I41 -> 0 | L41: =D41+F41-H41-J41 -> 0
A42: 2112 | B42: PAKAR METEOROLOGI | C42: 0 | D42: 0 | E42: 0 | F42: 0 | G42: 0 | H42: 0 | I42: 0 | J42: 0 | K42: =C42+E42-G42-I42 -> 0 | L42: =D42+F42-H42-J42 -> 0
A43: 2113 | B43: PAKAR KIMIA | C43: 0 | D43: 0 | E43: 0 | F43: 0 | G43: 0 | H43: 0 | I43: 0 | J43: 0 | K43: =C43+E43-G43-I43 -> 0 | L43: =D43+F43-H43-J43 -> 0
A44: 2114 | B44: PAKAR GEOLOGI DAN GEOFISIKA | C44: 0 | D44: 0 | E44: 0 | F44: 0 | G44: 0 | H44: 0 | I44: 0 | J44: 0 | K44: =C44+E44-G44-I44 -> 0 | L44: =D44+F44-H44-J44 -> 0
A45: 2121 | B45: PAKAR MATEMATIKA DAN PROFESI YANG SEJENIS | C45: 0 | D45: 0 | E45: 0 | F45: 0 | G45: 0 | H45: 0 | I45: 0 | J45: 0 | K45: =C45+E45-G45-I45 -> 0 | L45: =D45+F45-H45-J45 -> 0
A46: 2122 | B46: PAKAR STATISTIK | C46: 0 | D46: 4 | E46: 0 | F46: 0 | G46: 0 | H46: 0 | I46: 0 | J46: 0 | K46: =C46+E46-G46-I46 -> 0 | L46: =D46+F46-H46-J46 -> 4
A47: 2131 | B47: PERANCANG DAN ANALIS SISTEM KOMPUTER | C47: 0 | D47: 1 | E47: 0 | F47: 0 | G47: 0 | H47: 0 | I47: 0 | J47: 0 | K47: =C47+E47-G47-I47 -> 0 | L47: =D47+F47-H47-J47 -> 1
A48: 2132 | B48: PROGRAMER KOMPUTER | C48: 165 | D48: 67 | E48: 0 | F48: 0 | G48: 0 | H48: 0 | I48: 0 | J48: 0 | K48: =C48+E48-G48-I48 -> 165 | L48: =D48+F48-H48-J48 -> 67
A49: 2139 | B49: PAKAR KOMPUTER YTDL | C49: 0 | D49: 0 | E49: 0 | F49: 0 | G49: 0 | H49: 0 | I49: 0 | J49: 0 | K49: =C49+E49-G49-I49 -> 0 | L49: =D49+F49-H49-J49 -> 0
A50: 2141 | B50: ARSITEK PERENCANA TATA KOTA & LALU LINTAS | C50: 2 | D50: 2 | E50: 0 | F50: 0 | G50: 0 | H50: 0 | I50: 0 | J50: 0 | K50: =C50+E50-G50-I50 -> 2 | L50: =D50+F50-H50-J50 -> 2
A51: 2142 | B51: PEREKAYASA SIPIL | C51: 1 | D51: 6 | E51: 0 | F51: 0 | G51: 0 | H51: 0 | I51: 0 | J51: 0 | K51: =C51+E51-G51-I51 -> 1 | L51: =D51+F51-H51-J51 -> 6
A52: 2143 | B52: PEREKAYASA ELEKTRO | C52: 0 | D52: 0 | E52: 0 | F52: 0 | G52: 0 | H52: 0 | I52: 0 | J52: 0 | K52: =C52+E52-G52-I52 -> 0 | L52: =D52+F52-H52-J52 -> 0
... A92: 2460 | B92: PAKAR KEAGAMAAN | C92: 0 | D92: 0 | E92: 0 | F92: 0 | G92: 0 | H92: 0 | I92: 0 | J92: 0 | K92: =C92+E92-G92-I92 -> 0 | L92: =D92+F92-H92-J92 -> 0
A93: 3 | B93: TEKNISI DAN KELOMPOK JABATAN YANG SEJENIS
A94: 3111 | B94: TEKNISI ILMU KIMIA DAN FISIKA | C94: 0 | D94: 0 | E94: 0 | F94: 0 | G94: 0 | H94: 0 | I94: 0 | J94: 0 | K94: =C94+E94-G94-I94 -> 0 | L94: =D94+F94-H94-J94 -> 0
A95: 3112 | B95: TEKNISI PEREKAYASAAN SIPIL | C95: 9 | D95: 17 | E95: 0 | F95: 0 | G95: 0 | H95: 0 | I95: 0 | J95: 0 | K95: =C95+E95-G95-I95 -> 9 | L95: =D95+F95-H95-J95 -> 17
A96: 3113 | B96: TEKNISI PEREKAYASAAN LISTRIK | C96: 2 | D96: 0 | E96: 0 | F96: 0 | G96: 0 | H96: 0 | I96: 0 | J96: 0 | K96: =C96+E96-G96-I96 -> 2 | L96: =D96+F96-H96-J96 -> 0
...

Sheet ipk3.4
A1: IPK III/4: LOWONGAN KERJA YANG TERDAFTAR, DITEMPATKAN DAN DIHAPUSKAN DI
A2: KABUPATEN PASER MENURUT JENIS PENDIDIKAN
A3: ='ipk3.3'!A3 -> PADA TANGGAL : 1 AGUSTUS 2025 s/d 31 AGUSTUS 2025
A5: Kode | B5: Jenis Pendidikan | C5: Sisa akhir bulan lalu | E5: Pendaftaran bulan ini | G5: Penempatan bulan ini | I5: Penghapuskan bulan ini | K5: Sisa akhir bulan ini
C6: L | D6: W | E6: L | F6: W | G6: L | H6: W | I6: L | J6: W | K6: L | L6: W
A7: 1 | C7: 2 | D7: 3 | E7: 4 | F7: 5 | G7: 6 | H7: 7 | I7: 8 | J7: 9 | K7: 10 | L7: 11
A8: 1000 | B8: SEKOLAH DASAR
A9: 1101 | B9: TIDAK TAMAT SD | C9: 0 | D9: 0 | E9: 0 | F9: 0 | G9: 0 | H9: 0 | I9: 0 | J9: 0 | K9: =C9+E9-G9-I9 -> 0 | L9: =D9+F9-H9-J9 -> 0
A10: 1102 | B10: TAMAT SD | C10: 122 | D10: 0 | E10: 0 | F10: 0 | G10: 0 | H10: 0 | I10: 0 | J10: 0 | K10: =C10+E10-G10-I10 -> 122 | L10: =D10+F10-H10-J10 -> 0
A11: 1103 | B11: SETINGKAT SD | C11: 0 | D11: 0 | E11: 0 | F11: 0 | G11: 0 | H11: 0 | I11: 0 | J11: 0 | K11: =C11+E11-G11-I11 -> 0 | L11: =D11+F11-H11-J11 -> 0
A12: 1199 | B12: SD - TAK TERDEFINISI | C12: 0 | D12: 0 | E12: 0 | F12: 0 | G12: 0 | H12: 0 | I12: 0 | J12: 0 | K12: =C12+E12-G12-I12 -> 0 | L12: =D12+F12-H12-J12 -> 0
A13: 2000 | B13: PENDIDIKAN MENENGAH PERTAMA
A14: 2101 | B14: SEKOLAH MENENGAH PERTAMA | C14: 2 | D14: 0 | E14: 0 | F14: 0 | G14: 0 | H14: 0 | I14: 0 | J14: 0 | K14: =C14+E14-G14-I14 -> 2 | L14: =D14+F14-H14-J14 -> 0
A15: 2102 | B15: MADRASAH DINIYAH SANAWIYAH | C15: 0 | D15: 0 | E15: 0 | F15: 0 | G15: 0 | H15: 0 | I15: 0 | J15: 0 | K15: =C15+E15-G15-I15 -> 0 | L15: =D15+F15-H15-J15 -> 0
A16: 2103 | B16: LAINNYA | C16: 0 | D16: 0 | E16: 0 | F16: 0 | G16: 0 | H16: 0 | I16: 0 | J16: 0 | K16: =C16+E16-G16-I16 -> 0 | L16: =D16+F16-H16-J16 -> 0
A17: 2104 | B17: SLTP KEJURUAN | C17: 0 | D17: 0 | E17: 0 | F17: 0 | G17: 0 | H17: 0 | I17: 0 | J17: 0 | K17: =C17+E17-G17-I17 -> 0 | L17: =D17+F17-H17-J17 -> 0
A18: 2199 | B18: SLTP - TAK TERDEFINISI | C18: 0 | D18: 0 | E18: 0 | F18: 0 | G18: 0 | H18: 0 | I18: 0 | J18: 0 | K18: =C18+E18-G18-I18 -> 0 | L18: =D18+F18-H18-J18 -> 0
A19: 3000 | B19: PENDIDIKAN MENENGAH ATAS
A20: 3101 | B20: TEKNIK BANGUNAN | C20: 1 | D20: 0 | E20: 0 | F20: 0 | G20: 0 | H20: 0 | I20: 0 | J20: 0 | K20: =C20+E20-G20-I20 -> 1 | L20: =D20+F20-H20-J20 -> 0
A21: 3102 | B21: TEKNIK PLUMBING DAN SANITASI | C21: 0 | D21: 0 | E21: 0 | F21: 0 | G21: 0 | H21: 0 | I21: 0 | J21: 0 | K21: =C21+E21-G21-I21 -> 0 | L21: =D21+F21-H21-J21 -> 0
A22: 3103 | B22: TEKNIK SURVEI DAN PEMETAAN | C22: 0 | D22: 0 | E22: 0 | F22: 0 | G22: 0 | H22: 0 | I22: 0 | J22: 0 | K22: =C22+E22-G22-I22 -> 0 | L22: =D22+F22-H22-J22 -> 0
A23: 3104 | B23: TEKNIK KETENAGALISTRIKAN | C23: 19 | D23: 0 | E23: 0 | F23: 0 | G23: 0 | H23: 0 | I23: 0 | J23: 0 | K23: =C23+E23-G23-I23 -> 19 | L23: =D23+F23-H23-J23 -> 0
A24: 3105 | B24: TEKNIK PENDINGINAN DAN TATA UDARA | C24: 1 | D24: 0 | E24: 0 | F24: 0 | G24: 0 | H24: 0 | I24: 0 | J24: 0 | K24: =C24+E24-G24-I24 -> 1 | L24: =D24+F24-H24-J24 -> 0
A25: 3106 | B25: TEKNIK MESIN | C25: 41 | D25: 0 | E25: 0 | F25: 0 | G25: 0 | H25: 0 | I25: 0 | J25: 0 | K25: =C25+E25-G25-I25 -> 41 | L25: =D25+F25-H25-J25 -> 0
A26: 3107 | B26: TEKNIK OTOMOTIF | C26: 57 | D26: 0 | E26: 0 | F26: 0 | G26: 0 | H26: 0 | I26: 0 | J26: 0 | K26: =C26+E26-G26-I26 -> 57 | L26: =D26+F26-H26-J26 -> 0
A27: 3108 | B27: TEKNOLOGI PESAWAT UDARA | C27: 1 | D27: 0 | E27: 0 | F27: 0 | G27: 0 | H27: 0 | I27: 0 | J27: 0 | K27: =C27+E27-G27-I27 -> 1 | L27: =D27+F27-H27-J27 -> 0
A28: 3109 | B28: TEKNIK PERKAPALAN | C28: 0 | D28: 0 | E28: 0 | F28: 0 | G28: 0 | H28: 0 | I28: 0 | J28: 0 | K28: =C28+E28-G28-I28 -> 0 | L28: =D28+F28-H28-J28 -> 0
A29: 3110 | B29: TEKNOLOGI TEKSTIL | C29: 0 | D29: 0 | E29: 0 | F29: 0 | G29: 0 | H29: 0 | I29: 0 | J29: 0 | K29: =C29+E29-G29-I29 -> 0 | L29: =D29+F29-H29-J29 -> 0
A30: 3111 | B30: TEKNIK GRAFIKA | C30: 0 | D30: 0 | E30: 0 | F30: 0 | G30: 0 | H30: 0 | I30: 0 | J30: 0 | K30: =C30+E30-G30-I30 -> 0 | L30: =D30+F30-H30-J30 -> 0
A31: 3112 | B31: GEOLOGI PERTAMBANGAN | C31: 2 | D31: 0 | E31: 0 | F31: 0 | G31: 0 | H31: 0 | I31: 0 | J31: 0 | K31: =C31+E31-G31-I31 -> 2 | L31: =D31+F31-H31-J31 -> 0
... A63: 3802 | B63: MADRASAH DINIYAH ALIYAH | C63: 25 | D63: 1 | E63: 0 | F63: 0 | G63: 0 | H63: 0 | I63: 0 | J63: 0 | K63: =C63+E63-G63-I63 -> 25 | L63: =D63+F63-H63-J63 -> 1
A64: 4000 | B64: DIPLOMA I / AKTA I
A65: 4101 | B65: PENDIDIKAN | C65: 0 | D65: 0 | E65: 0 | F65: 0 | G65: 0 | H65: 0 | I65: 0 | J65: 0 | K65: =C65+E65-G65-I65 -> 0 | L65: =D65+F65-H65-J65 -> 0
A66: 4102 | B66: PENDIDIKAN LUAR SEKOLAH | C66: 0 | D66: 0 | E66: 0 | F66: 0 | G66: 0 | H66: 0 | I66: 0 | J66: 0 | K66: =C66+E66-G66-I66 -> 0 | L66: =D66+F66-H66-J66 -> 0
A67: 4103 | B67: PENDIDIKAN KESEJAHTERAAN SOSIAL | C67: 0 | D67: 0 | E67: 0 | F67: 0 | G67: 0 | H67: 0 | I67: 0 | J67: 0 | K67: =C67+E67-G67-I67 -> 0 | L67: =D67+F67-H67-J67 -> 0
A68: 4104 | B68: PSIKOLOGI | C68: 0 | D68: 0 | E68: 0 | F68: 0 | G68: 0 | H68: 0 | I68: 0 | J68: 0 | K68: =C68+E68-G68-I68 -> 0 | L68: =D68+F68-H68-J68 -> 0
A69: 4105 | B69: ILMU PENGETAHUAN SOSIAL | C69: 0 | D69: 0 | E69: 0 | F69: 0 | G69: 0 | H69: 0 | I69: 0 | J69: 0 | K69: =C69+E69-G69-I69 -> 0 | L69: =D69+F69-H69-J69 -> 0
A70: 4106 | B70: PENDIDIKAN MORAL PANCASILA | C70: 0 | D70: 0 | E70: 0 | F70: 0 | G70: 0 | H70: 0 | I70: 0 | J70: 0 | K70: =C70+E70-G70-I70 -> 0 | L70: =D70+F70-H70-J70 -> 0
A71: 4107 | B71: ADMINISTRASI KEUANGAN | C71: 0 | D71: 0 | E71: 0 | F71: 0 | G71: 0 | H71: 0 | I71: 0 | J71: 0 | K71: =C71+E71-G71-I71 -> 0 | L71: =D71+F71-H71-J71 -> 0
A72: 4108 | B72: ANTROPOLOGI | C72: 0 | D72: 0 | E72: 0 | F72: 0 | G72: 0 | H72: 0 | I72: 0 | J72: 0 | K72: =C72+E72-G72-I72 -> 0 | L72: =D72+F72-H72-J72 -> 0
...

Sheet ipk3.5
A1: IPK III/5 : LOWONGAN KERJA YANG TERDAFTAR, DITEMPATKAN DAN DIHAPUSKAN DI
A2: KABUPATEN PASER MENURUT GOLONGAN JABATAN
A3: ='ipk3.4'!A3 -> PADA TANGGAL : 1 AGUSTUS 2025 s/d 31 AGUSTUS 2025
A5: Kode | B5: Jenis Golongan Pokok Jabatan | C5: Sisa akhir bulan lalu | E5: Pendaftaran bulan ini | G5: Penempatan bulan ini | I5: Penghapuskan bulan ini | K5: Sisa akhir bulan ini
C6: L | D6: W | E6: L | F6: W | G6: L | H6: W | I6: L | J6: W | K6: L | L6: W
A7: 1 | C7: 2 | D7: 3 | E7: 4 | F7: 5 | G7: 6 | H7: 7 | I7: 8 | J7: 9 | K7: 10 | L7: 11
A8: 0 | B8: ANGGOTA ANGKATAN BERSENJATA (KECUALI KEPOLISIAN)
A9: 110 | B9: ANGGOTA ANGKATAN BERSENJATA | C9: 0 | D9: 0 | E9: 0 | F9: 0 | G9: 0 | H9: 0 | I9: 0 | J9: 0 | K9: =C9+E9-G9-I9 -> 0 | L9: =D9+F9-H9-J9 -> 0
A10: 1 | B10: ANGGOTA BADAN LEGISLATIF, PEJABAT TINGGI PEMERINTAH
A11: 1110 | B11: ANGGOTA BADAN LEGISLATIF | C11: 0 | D11: 0 | E11: 0 | F11: 0 | G11: 0 | H11: 0 | I11: 0 | J11: 0 | K11: =C11+E11-G11-I11 -> 0 | L11: =D11+F11-H11-J11 -> 0
A12: 1120 | B12: PEJABAT TINGGI PEMERINTAH | C12: 0 | D12: 0 | E12: 0 | F12: 0 | G12: 0 | H12: 0 | I12: 0 | J12: 0 | K12: =C12+E12-G12-I12 -> 0 | L12: =D12+F12-H12-J12 -> 0
A13: 1130 | B13: KEPALA DESA DAN LURAH | C13: 0 | D13: 0 | E13: 0 | F13: 0 | G13: 0 | H13: 0 | I13: 0 | J13: 0 | K13: =C13+E13-G13-I13 -> 0 | L13: =D13+F13-H13-J13 -> 0
A14: 1141 | B14: PEMIMPIN ORGANISASI PARTAI POLITIK | C14: 0 | D14: 0 | E14: 0 | F14: 0 | G14: 0 | H14: 0 | I14: 0 | J14: 0 | K14: =C14+E14-G14-I14 -> 0 | L14: =D14+F14-H14-J14 -> 0
A15: 1142 | B15: PIMPINAN ORGANISASI PENGUSAHA, PEKERJA DAN ORGANISASI YANG BERKAITAN DENGAN KEPENTINGAN DARI ORGANISASI EKONOMI | C15: 0 | D15: 0 | E15: 0 | F15: 0 | G15: 0 | H15: 0 | I15: 0 | J15: 0 | K15: =C15+E15-G15-I15 -> 0 | L15: =D15+F15-H15-J15 -> 0
A16: 1143 | B16: PIMPINAN ORGANISASI KEMANUSIAAN DAN ORGANISASI KHUSUS | C16: 0 | D16: 0 | E16: 0 | F16: 0 | G16: 0 | H16: 0 | I16: 0 | J16: 0 | K16: =C16+E16-G16-I16 -> 0 | L16: =D16+F16-H16-J16 -> 0
A17: 1210 | B17: DIREKTUR DAN KEPALA EKSEKUTIF | C17: 0 | D17: 0 | E17: 0 | F17: 0 | G17: 0 | H17: 0 | I17: 0 | J17: 0 | K17: =C17+E17-G17-I17 -> 0 | L17: =D17+F17-H17-J17 -> 0
A18: 1221 | B18: MANAJER PRODUKSI DAN OPERASI DALAM BIDANG PERTANIAN PERBURUAN DAN PERIKANAN | C18: 0 | D18: 0 | E18: 0 | F18: 0 | G18: 0 | H18: 0 | I18: 0 | J18: 0 | K18: =C18+E18-G18-I18 -> 0 | L18: =D18+F18-H18-J18 -> 0
A19: 1223 | B19: MANAJER PRODUKSI DAN OPERASI DALAM BIDANG KONSTRUKSI | C19: 0 | D19: 0 | E19: 0 | F19: 0 | G19: 0 | H19: 0 | I19: 0 | J19: 0 | K19: =C19+E19-G19-I19 -> 0 | L19: =D19+F19-H19-J19 -> 0
A20: 1224 | B20: MANAJER PRODUKSI DAN OPERASI DOKUMEN DALAM BIDANG PERDAGANGA BESAR DAN ECERAN | C20: 0 | D20: 0 | E20: 0 | F20: 0 | G20: 0 | H20: 0 | I20: 0 | J20: 0 | K20: =C20+E20-G20-I20 -> 0 | L20: =D20+F20-H20-J20 -> 0
A21: 1225 | B21: MANAJER PRODUKSI DAN OPERASI DALAM BIDANG HOTEL DAN RESTORAN | C21: 0 | D21: 0 | E21: 0 | F21: 0 | G21: 0 | H21: 0 | I21: 0 | J21: 0 | K21: =C21+E21-G21-I21 -> 0 | L21: =D21+F21-H21-J21 -> 0
A22: 1226 | B22: MANAJER PRODUKSI DAN OPERASI DALAM BIDANG ANGKUTAN (LAYANAN TELEKOMUNIKASI) PERGUDANGAN & KOMUNIKASI | C22: 0 | D22: 0 | E22: 0 | F22: 0 | G22: 0 | H22: 0 | I22: 0 | J22: 0 | K22: =C22+E22-G22-I22 -> 0 | L22: =D22+F22-H22-J22 -> 0
... A39: 1319 | B39: MANAJER UMUM YANG TIDAK DAPAT DIKLASIFIKASIKAN PADA SUB GOL 1311 SAMPAI DENGAN 1318 | C39: 0 | D39: 0 | E39: 0 | F39: 0 | G39: 0 | H39: 0 | I39: 0 | J39: 0 | K39: =C39+E39-G39-I39 -> 0 | L39: =D39+F39-H39-J39 -> 0
A40: 2 | B40: TENAGA PROFESIONAL
A41: 2111 | B41: PAKAR FISIKA DAN ASTRONOMI | C41: 0 | D41: 0 | E41: 0 | F41: 0 | G41: 0 | H41: 0 | I41: 0 | J41: 0 | K41: =C41+E41-G41-I41 -> 0 | L41: =D41+F41-H41-J41 -> 0
A42: 2112 | B42: PAKAR METEOROLOGI | C42: 0 | D42: 0 | E42: 0 | F42: 0 | G42: 0 | H42: 0 | I42: 0 | J42: 0 | K42: =C42+E42-G42-I42 -> 0 | L42: =D42+F42-H42-J42 -> 0
A43: 2113 | B43: PAKAR KIMIA | C43: 0 | D43: 0 | E43: 0 | F43: 0 | G43: 0 | H43: 0 | I43: 0 | J43: 0 | K43: =C43+E43-G43-I43 -> 0 | L43: =D43+F43-H43-J43 -> 0
A44: 2114 | B44: PAKAR GEOLOGI DAN GEOFISIKA | C44: 0 | D44: 0 | E44: 0 | F44: 0 | G44: 0 | H44: 0 | I44: 0 | J44: 0 | K44: =C44+E44-G44-I44 -> 0 | L44: =D44+F44-H44-J44 -> 0
A45: 2121 | B45: PAKAR MATEMATIKA DAN PROFESI YANG SEJENIS | C45: 0 | D45: 0 | E45: 0 | F45: 0 | G45: 0 | H45: 0 | I45: 0 | J45: 0 | K45: =C45+E45-G45-I45 -> 0 | L45: =D45+F45-H45-J45 -> 0
A46: 2122 | B46: PAKAR STATISTIK | C46: 0 | D46: 0 | E46: 0 | F46: 0 | G46: 0 | H46: 0 | I46: 0 | J46: 0 | K46: =C46+E46-G46-I46 -> 0 | L46: =D46+F46-H46-J46 -> 0
A47: 2131 | B47: PERANCANG DAN ANALIS SISTEM KOMPUTER | C47: 0 | D47: 0 | E47: 0 | F47: 0 | G47: 0 | H47: 0 | I47: 0 | J47: 0 | K47: =C47+E47-G47-I47 -> 0 | L47: =D47+F47-H47-J47 -> 0
A48: 2132 | B48: PROGRAMER KOMPUTER | C48: 0 | D48: 0 | E48: 0 | F48: 0 | G48: 0 | H48: 0 | I48: 0 | J48: 0 | K48: =C48+E48-G48-I48 -> 0 | L48: =D48+F48-H48-J48 -> 0
A49: 2139 | B49: PAKAR KOMPUTER YTDL | C49: 0 | D49: 0 | E49: 0 | F49: 0 | G49: 0 | H49: 0 | I49: 0 | J49: 0 | K49: =C49+E49-G49-I49 -> 0 | L49: =D49+F49-H49-J49 -> 0
A50: 2141 | B50: ARSITEK PERENCANA TATA KOTA & LALU LINTAS | C50: 0 | D50: 0 | E50: 0 | F50: 0 | G50: 0 | H50: 0 | I50: 0 | J50: 0 | K50: =C50+E50-G50-I50 -> 0 | L50: =D50+F50-H50-J50 -> 0
A51: 2142 | B51: PEREKAYASA SIPIL | C51: 0 | D51: 0 | E51: 0 | F51: 0 | G51: 0 | H51: 0 | I51: 0 | J51: 0 | K51: =C51+E51-G51-I51 -> 0 | L51: =D51+F51-H51-J51 -> 0
A52: 2143 | B52: PEREKAYASA ELEKTRO | C52: 0 | D52: 0 | E52: 0 | F52: 0 | G52: 0 | H52: 0 | I52: 0 | J52: 0 | K52: =C52+E52-G52-I52 -> 0 | L52: =D52+F52-H52-J52 -> 0
... A92: 2460 | B92: PAKAR KEAGAMAAN | C92: 0 | D92: 0 | E92: 0 | F92: 0 | G92: 0 | H92: 0 | I92: 0 | J92: 0 | K92: =C92+E92-G92-I92 -> 0 | L92: =D92+F92-H92-J92 -> 0
A93: 3 | B93: TEKNISI DAN KELOMPOK JABATAN YANG SEJENIS
A94: 3111 | B94: TEKNISI ILMU KIMIA DAN FISIKA | C94: 0 | D94: 0 | E94: 0 | F94: 0 | G94: 0 | H94: 0 | I94: 0 | J94: 0 | K94: =C94+E94-G94-I94 -> 0 | L94: =D94+F94-H94-J94 -> 0
A95: 3112 | B95: TEKNISI PEREKAYASAAN SIPIL | C95: 1 | D95: 0 | E95: 0 | F95: 0 | G95: 0 | H95: 0 | I95: 0 | J95: 0 | K95: =C95+E95-G95-I95 -> 1 | L95: =D95+F95-H95-J95 -> 0
A96: 3113 | B96: TEKNISI PEREKAYASAAN LISTRIK | C96: 0 | D96: 0 | E96: 0 | F96: 0 | G96: 0 | H96: 0 | I96: 0 | J96: 0 | K96: =C96+E96-G96-I96 -> 0 | L96: =D96+F96-H96-J96 -> 0
...

Sheet ipk.3.6
A1: IPK III/6 : LOWONGAN KERJA YANG TERDAFTAR, DITEMPATKAN DAN DIHAPUSKAN DI
A2: KABUPATEN PASER MENURUT GOLONGAN POKOK LAPANGAN USAHA
A3: ='ipk3.5'!A3 -> PADA TANGGAL : 1 AGUSTUS 2025 s/d 31 AGUSTUS 2025
A5: Kode | B5: Golongan Pokok Lapangan Usaha | C5: Sisa akhir bulan lalu | E5: Pendaftaran bulan ini | G5: Penempatan bulan ini | I5: Penghapuskan bulan ini | K5: Sisa akhir bulan ini
C6: L | D6: W | E6: L | F6: W | G6: L | H6: W | I6: L | J6: W | K6: L | L6: W
A7: 1 | C7: 2 | D7: 3 | E7: 4 | F7: 5 | G7: 6 | H7: 7 | I7: 8 | J7: 9 | K7: 10 | L7: 11
A8: A | B8: PERTANIAN, KEHUTANAN DAN PERIKANAN
A9: 11 | B9: PERTANIAN TANAMAN SEMUSIM | C9: 0 | D9: 0 | E9: 0 | F9: 0 | G9: 0 | H9: 0 | I9: 0 | J9: 0 | K9: =C9+E9-G9-I9 -> 0 | L9: =D9+F9-H9-J9 -> 0
A10: 12 | B10: PERTANIAN TANAMAN TAHUNAN | C10: 147 | D10: 7 | E10: 0 | F10: 0 | G10: 0 | H10: 0 | I10: 0 | J10: 0 | K10: =C10+E10-G10-I10 -> 147 | L10: =D10+F10-H10-J10 -> 7
A11: 13 | B11: PERTANIAN TANAMAN HIAS DAN PENGEMBANGBIAKAN TANAMAN | C11: 0 | D11: 0 | E11: 0 | F11: 0 | G11: 0 | H11: 0 | I11: 0 | J11: 0 | K11: =C11+E11-G11-I11 -> 0 | L11: =D11+F11-H11-J11 -> 0
A12: 14 | B12: PETERNAKAN | C12: 0 | D12: 0 | E12: 0 | F12: 0 | G12: 0 | H12: 0 | I12: 0 | J12: 0 | K12: =C12+E12-G12-I12 -> 0 | L12: =D12+F12-H12-J12 -> 0
A13: 16 | B13: JASA PENUNJANG PERTANIAN DAN PASCA PANEN | C13: 0 | D13: 0 | E13: 0 | F13: 0 | G13: 0 | H13: 0 | I13: 0 | J13: 0 | K13: =C13+E13-G13-I13 -> 0 | L13: =D13+F13-H13-J13 -> 0
A14: 17 | B14: PERBURUAN, PENANGKAPAN DAN PENANGKARAN SATWA LIAR | C14: 0 | D14: 0 | E14: 0 | F14: 0 | G14: 0 | H14: 0 | I14: 0 | J14: 0 | K14: =C14+E14-G14-I14 -> 0 | L14: =D14+F14-H14-J14 -> 0
A15: 21 | B15: PENGUSAHAAN HUTAN | C15: 0 | D15: 0 | E15: 0 | F15: 0 | G15: 0 | H15: 0 | I15: 0 | J15: 0 | K15: =C15+E15-G15-I15 -> 0 | L15: =D15+F15-H15-J15 -> 0
A16: 22 | B16: PENEBANGAN DAN PEMUNGUTAN KAYU | C16: 0 | D16: 0 | E16: 0 | F16: 0 | G16: 0 | H16: 0 | I16: 0 | J16: 0 | K16: =C16+E16-G16-I16 -> 0 | L16: =D16+F16-H16-J16 -> 0
A17: 23 | B17: PEMUNGUTAN HASIL HUTAN BUKAN KAYU | C17: 0 | D17: 0 | E17: 0 | F17: 0 | G17: 0 | H17: 0 | I17: 0 | J17: 0 | K17: =C17+E17-G17-I17 -> 0 | L17: =D17+F17-H17-J17 -> 0
A18: 24 | B18: JASA PENUNJANG KEHUTANAN | C18: 0 | D18: 0 | E18: 0 | F18: 0 | G18: 0 | H18: 0 | I18: 0 | J18: 0 | K18: =C18+E18-G18-I18 -> 0 | L18: =D18+F18-H18-J18 -> 0
A19: 31 | B19: PERIKANAN TANGKAP | C19: 0 | D19: 0 | E19: 0 | F19: 0 | G19: 0 | H19: 0 | I19: 0 | J19: 0 | K19: =C19+E19-G19-I19 -> 0 | L19: =D19+F19-H19-J19 -> 0
A20: 32 | B20: PERIKANAN BUDIDAYA | C20: 0 | D20: 0 | E20: 0 | F20: 0 | G20: 0 | H20: 0 | I20: 0 | J20: 0 | K20: =C20+E20-G20-I20 -> 0 | L20: =D20+F20-H20-J20 -> 0
A21: B | B21: PERTAMBANGAN DAN PENGGALIAN
A22: 51 | B22: PERTAMBANGAN BATU BARA | C22: 305 | D22: 0 | E22: 0 | F22: 0 | G22: 0 | H22: 0 | I22: 0 | J22: 0 | K22: =C22+E22-G22-I22 -> 305 | L22: =D22+F22-H22-J22 -> 0
A23: 52 | B23: PERTAMBANGAN LIGNIT | C23: 0 | D23: 0 | E23: 0 | F23: 0 | G23: 0 | H23: 0 | I23: 0 | J23: 0 | K23: =C23+E23-G23-I23 -> 0 | L23: =D23+F23-H23-J23 -> 0
A24: 61 | B24: PERTAMBANGAN MINYAK BUMI | C24: 0 | D24: 0 | E24: 0 | F24: 0 | G24: 0 | H24: 0 | I24: 0 | J24: 0 | K24: =C24+E24-G24-I24 -> 0 | L24: =D24+F24-H24-J24 -> 0
A25: 62 | B25: PERTAMBANGAN GAS ALAM DAN PANAS BUMI | C25: 0 | D25: 0 | E25: 0 | F25: 0 | G25: 0 | H25: 0 | I25: 0 | J25: 0 | K25: =C25+E25-G25-I25 -> 0 | L25: =D25+F25-H25-J25 -> 0
A26: 71 | B26: PERTAMBANGAN PASIR BESI DAN BIJIH BESI | C26: 0 | D26: 0 | E26: 0 | F26: 0 | G26: 0 | H26: 0 | I26: 0 | J26: 0 | K26: =C26+E26-G26-I26 -> 0 | L26: =D26+F26-H26-J26 -> 0
A27: 72 | B27: PERTAMBANGAN BIJIH LOGAM YANG TIDAK MENGANDUNG BESI,TIDAK TERMASUK BIJIH LOGAM MULIA | C27: 0 | D27: 0 | E27: 0 | F27: 0 | G27: 0 | H27: 0 | I27: 0 | J27: 0 | K27: =C27+E27-G27-I27 -> 0 | L27: =D27+F27-H27-J27 -> 0
A28: 73 | B28: PERTAMBANGAN BIJIH LOGAM MULIA | C28: 0 | D28: 0 | E28: 0 | F28: 0 | G28: 0 | H28: 0 | I28: 0 | J28: 0 | K28: =C28+E28-G28-I28 -> 0 | L28: =D28+F28-H28-J28 -> 0
A29: 81 | B29: PENGGALIAN BATU, PASIR DAN TANAH LIAT | C29: 0 | D29: 0 | E29: 0 | F29: 0 | G29: 0 | H29: 0 | I29: 0 | J29: 0 | K29: =C29+E29-G29-I29 -> 0 | L29: =D29+F29-H29-J29 -> 0
A30: 89 | B30: PERTAMBANGAN DAN PENGGALIAN LAINNYA YTDL | C30: 0 | D30: 0 | E30: 0 | F30: 0 | G30: 0 | H30: 0 | I30: 0 | J30: 0 | K30: =C30+E30-G30-I30 -> 0 | L30: =D30+F30-H30-J30 -> 0
A31: 91 | B31: JASA PERTAMBANGAN MINYAK BUMI DAN GAS ALAM | C31: 0 | D31: 0 | E31: 0 | F31: 0 | G31: 0 | H31: 0 | I31: 0 | J31: 0 | K31: =C31+E31-G31-I31 -> 0 | L31: =D31+F31-H31-J31 -> 0
A32: 99 | B32: JASA PERTAMBANGAN DAN PENGGALIAN LAINNYA | C32: 4 | D32: 1 | E32: 0 | F32: 0 | G32: 0 | H32: 0 | I32: 0 | J32: 0 | K32: =C32+E32-G32-I32 -> 4 | L32: =D32+F32-H32-J32 -> 1
A33: C | B33: INDUSTRI PENGOLAHAN
A34: 101 | B34: INDUSTRI PENGOLAHAN DAN PENGAWETAN DAGING | C34: 0 | D34: 0 | E34: 0 | F34: 0 | G34: 0 | H34: 0 | I34: 0 | J34: 0 | K34: =C34+E34-G34-I34 -> 0 | L34: =D34+F34-H34-J34 -> 0
A35: 102 | B35: INDUSTRI PENGOLAHAN DAN PENGAWETAN IKAN DAN BIOTA AIR | C35: 0 | D35: 0 | E35: 0 | F35: 0 | G35: 0 | H35: 0 | I35: 0 | J35: 0 | K35: =C35+E35-G35-I35 -> 0 | L35: =D35+F35-H35-J35 -> 0
A36: 103 | B36: INDUSTRI PENGOLAHAN DAN PENGAWETAN BUAH-BUAHAN DAN SAYURAN | C36: 0 | D36: 0 | E36: 0 | F36: 0 | G36: 0 | H36: 0 | I36: 0 | J36: 0 | K36: =C36+E36-G36-I36 -> 0 | L36: =D36+F36-H36-J36 -> 0
A37: 104 | B37: INDUSTRI MINYAK MAKAN DAN LEMAK NABATI DAN HEWANI | C37: 0 | D37: 0 | E37: 0 | F37: 0 | G37: 0 | H37: 0 | I37: 0 | J37: 0 | K37: =C37+E37-G37-I37 -> 0 | L37: =D37+F37-H37-J37 -> 0
A38: 105 | B38: INDUSTRI PENGOLAHAN SUSU, PRODUK DARI SUSU DAN ES KRIM | C38: 0 | D38: 0 | E38: 0 | F38: 0 | G38: 0 | H38: 0 | I38: 0 | J38: 0 | K38: =C38+E38-G38-I38 -> 0 | L38: =D38+F38-H38-J38 -> 0
A39: 106 | B39: INDUSTRI PENGGILINGAN PADI-PADIAN, TEPUNG DAN PATI | C39: 0 | D39: 0 | E39: 0 | F39: 0 | G39: 0 | H39: 0 | I39: 0 | J39: 0 | K39: =C39+E39-G39-I39 -> 0 | L39: =D39+F39-H39-J39 -> 0
A40: 107 | B40: INDUSTRI MAKANAN LAINNYA | C40: 0 | D40: 0 | E40: 0 | F40: 0 | G40: 0 | H40: 0 | I40: 0 | J40: 0 | K40: =C40+E40-G40-I40 -> 0 | L40: =D40+F40-H40-J40 -> 0
A41: 108 | B41: INDUSTRI MAKANAN HEWAN | C41: 0 | D41: 0 | E41: 0 | F41: 0 | G41: 0 | H41: 0 | I41: 0 | J41: 0 | K41: =C41+E41-G41-I41 -> 0 | L41: =D41+F41-H41-J41 -> 0
...

Sheet ipk.3.7
A1: IPK III/7 : PENCARI KERJA YANG TERDAFTAR, DITEMPATKAN DAN DIHAPUSKAN
A2: DI KABUPATEN PASER MENURUT LAMA LULUSAN DAN TINGKAT PENDIDIKAN
A3: ='ipk.3.6'!A3 -> PADA TANGGAL : 1 AGUSTUS 2025 s/d 31 AGUSTUS 2025
A5: Kode | B5: Golongan Pokok Lapangan Usaha | C5: Sisa akhir bulan lalu | F5: Pendaftaran bulan ini | I5: Penempatan bulan ini | L5: Penghapuskan bulan ini | O5: Sisa akhir bulan ini
C6: (0-2) | D6: (3-5) | E6: (6+) | F6: (0-2) | G6: (3-5) | H6: (6+) | I6: (0-2) | J6: (3-5) | K6: (6+) | L6: (0-2) | M6: (3-5) | N6: (6+) | O6: (0-2) | P6: (3-5) | Q6: (6+)
A7: 1 | B7: 2 | C7: 3 | D7: 4 | E7: 5 | F7: 6 | G7: 7 | H7: 8 | I7: 9 | J7: 10 | K7: 11 | L7: 12 | M7: 13 | N7: 14 | O7: 15 | P7: 16 | Q7: 17
A8: 1001 | B8: BH & TIDAK TAMAT SD
A9: 1101 | B9: TIDAK TAMAT SD | C9: 5 | D9: 0 | E9: 0 | F9: 0 | G9: 0 | H9: 0 | I9: 0 | J9: 0 | K9: 0 | L9: 0 | M9: 0 | N9: 0 | O9: =C9+F9-I9-L9 -> 5 | P9: =D9+G9-J9-M9 -> 0 | Q9: =E9+H9-K9-N9 -> 0
A10: 1002 | B10: S.D
A11: 1102 | B11: TAMAT SD | C11: 0 | D11: 1 | E11: 11 | F11: 0 | G11: 0 | H11: 0 | I11: 0 | J11: 0 | K11: 0 | L11: 0 | M11: 0 | N11: 0 | O11: =C11+F11-I11-L11 -> 0 | P11: =D11+G11-J11-M11 -> 1 | Q11: =E11+H11-K11-N11 -> 11
A12: 1103 | B12: SETINGKAT SD | C12: 0 | D12: 0 | E12: 0 | F12: 0 | G12: 0 | H12: 0 | I12: 0 | J12: 0 | K12: 0 | L12: 0 | M12: 0 | N12: 0 | O12: =C12+F12-I12-L12 -> 0 | P12: =D12+G12-J12-M12 -> 0 | Q12: =E12+H12-K12-N12 -> 0
A13: 2001 | B13: SLTP UMUM
A14: 2101 | B14: SEKOLAH MENENGAH PERTAMA | C14: 4 | D14: 27 | E14: 24 | F14: 0 | G14: 0 | H14: 0 | I14: 0 | J14: 0 | K14: 0 | L14: 0 | M14: 0 | N14: 0 | O14: =C14+F14-I14-L14 -> 4 | P14: =D14+G14-J14-M14 -> 27 | Q14: =E14+H14-K14-N14 -> 24
A15: 2002 | B15: SLTP KEJURUAN
A16: 2104 | B16: SLTP KEJURUAN | C16: 2 | D16: 3 | E16: 6 | F16: 0 | G16: 0 | H16: 0 | I16: 0 | J16: 0 | K16: 0 | L16: 0 | M16: 0 | N16: 0 | O16: =C16+F16-I16-L16 -> 2 | P16: =D16+G16-J16-M16 -> 3 | Q16: =E16+H16-K16-N16 -> 6
A17: 2003 | B17: SETINGKAT SLTP
A18: 2103 | B18: SLTP - LAINNYA | C18: 4 | D18: 3 | E18: 3 | F18: 0 | G18: 0 | H18: 0 | I18: 0 | J18: 0 | K18: 0 | L18: 0 | M18: 0 | N18: 0 | O18: =C18+F18-I18-L18 -> 4 | P18: =D18+G18-J18-M18 -> 3 | Q18: =E18+H18-K18-N18 -> 3
A19: 3001 | B19: SMU
A20: 3801 | B20: SMU | C20: 354 | D20: 100 | E20: 135 | F20: 0 | G20: 0 | H20: 0 | I20: 0 | J20: 0 | K20: 0 | L20: 0 | M20: 0 | N20: 0 | O20: =C20+F20-I20-L20 -> 354 | P20: =D20+G20-J20-M20 -> 100 | Q20: =E20+H20-K20-N20 -> 135
A21: 3802 | B21: MADRASAH DINIYAH ALIYAH | C21: 57 | D21: 35 | E21: 20 | F21: 0 | G21: 0 | H21: 0 | I21: 0 | J21: 0 | K21: 0 | L21: 0 | M21: 0 | N21: 0 | O21: =C21+F21-I21-L21 -> 57 | P21: =D21+G21-J21-M21 -> 35 | Q21: =E21+H21-K21-N21 -> 20
B22: SMK
A23: 3100 | B23: SMK - TEKNOLOGI DAN REKAYASA
A24: 3101 | B24: TEKNIK BANGUNAN | C24: 24 | D24: 5 | E24: 3 | F24: 0 | G24: 0 | H24: 0 | I24: 0 | J24: 0 | K24: 0 | L24: 0 | M24: 0 | N24: 0 | O24: =C24+F24-I24-L24 -> 24 | P24: =D24+G24-J24-M24 -> 5 | Q24: =E24+H24-K24-N24 -> 3
A25: 3102 | B25: TEKNIK PLUMBING DAN SANITASI | C25: 0 | D25: 0 | E25: 0 | F25: 0 | G25: 0 | H25: 0 | I25: 0 | J25: 0 | K25: 0 | L25: 0 | M25: 0 | N25: 0 | O25: =C25+F25-I25-L25 -> 0 | P25: =D25+G25-J25-M25 -> 0 | Q25: =E25+H25-K25-N25 -> 0
A26: 3103 | B26: TEKNIK SURVEI DAN PEMETAAN | C26: 2 | D26: 0 | E26: 0 | F26: 0 | G26: 0 | H26: 0 | I26: 0 | J26: 0 | K26: 0 | L26: 0 | M26: 0 | N26: 0 | O26: =C26+F26-I26-L26 -> 2 | P26: =D26+G26-J26-M26 -> 0 | Q26: =E26+H26-K26-N26 -> 0
A27: 3104 | B27: TEKNIK KETENAGALISTRIKAN | C27: 58 | D27: 20 | E27: 13 | F27: 0 | G27: 0 | H27: 0 | I27: 0 | J27: 0 | K27: 0 | L27: 0 | M27: 0 | N27: 0 | O27: =C27+F27-I27-L27 -> 58 | P27: =D27+G27-J27-M27 -> 20 | Q27: =E27+H27-K27-N27 -> 13
A28: 3105 | B28: TEKNIK PENDINGINAN DAN TATA UDARA | C28: 3 | D28: 3 | E28: 1 | F28: 0 | G28: 0 | H28: 0 | I28: 0 | J28: 0 | K28: 0 | L28: 0 | M28: 0 | N28: 0 | O28: =C28+F28-I28-L28 -> 3 | P28: =D28+G28-J28-M28 -> 3 | Q28: =E28+H28-K28-N28 -> 1
A29: 3106 | B29: TEKNIK MESIN | C29: 26 | D29: 7 | E29: 29 | F29: 0 | G29: 0 | H29: 0 | I29: 0 | J29: 0 | K29: 0 | L29: 0 | M29: 0 | N29: 0 | O29: =C29+F29-I29-L29 -> 26 | P29: =D29+G29-J29-M29 -> 7 | Q29: =E29+H29-K29-N29 -> 29
A30: 3107 | B30: TEKNIK OTOMOTIF | C30: 160 | D30: 61 | E30: 39 | F30: 0 | G30: 0 | H30: 0 | I30: 0 | J30: 0 | K30: 0 | L30: 0 | M30: 0 | N30: 0 | O30: =C30+F30-I30-L30 -> 160 | P30: =D30+G30-J30-M30 -> 61 | Q30: =E30+H30-K30-N30 -> 39
A31: 3108 | B31: TEKNOLOGI PESAWAT UDARA | C31: 0 | D31: 1 | E31: 0 | F31: 0 | G31: 0 | H31: 0 | I31: 0 | J31: 0 | K31: 0 | L31: 0 | M31: 0 | N31: 0 | O31: =C31+F31-I31-L31 -> 0 | P31: =D31+G31-J31-M31 -> 1 | Q31: =E31+H31-K31-N31 -> 0
A32: 3109 | B32: TEKNIK PERKAPALAN | C32: 0 | D32: 0 | E32: 1 | F32: 0 | G32: 0 | H32: 0 | I32: 0 | J32: 0 | K32: 0 | L32: 0 | M32: 0 | N32: 0 | O32: =C32+F32-I32-L32 -> 0 | P32: =D32+G32-J32-M32 -> 0 | Q32: =E32+H32-K32-N32 -> 1
A33: 3110 | B33: TEKNOLOGI TEKSTIL | C33: 0 | D33: 0 | E33: 0 | F33: 0 | G33: 0 | H33: 0 | I33: 0 | J33: 0 | K33: 0 | L33: 0 | M33: 0 | N33: 0 | O33: =C33+F33-I33-L33 -> 0 | P33: =D33+G33-J33-M33 -> 0 | Q33: =E33+H33-K33-N33 -> 0
A34: 3111 | B34: TEKNIK GRAFIKA | C34: 0 | D34: 0 | E34: 0 | F34: 0 | G34: 0 | H34: 0 | I34: 0 | J34: 0 | K34: 0 | L34: 0 | M34: 0 | N34: 0 | O34: =C34+F34-I34-L34 -> 0 | P34: =D34+G34-J34-M34 -> 0 | Q34: =E34+H34-K34-N34 -> 0
A35: 3112 | B35: GEOLOGI PERTAMBANGAN | C35: 2 | D35: 5 | E35: 0 | F35: 0 | G35: 0 | H35: 0 | I35: 0 | J35: 0 | K35: 0 | L35: 0 | M35: 0 | N35: 0 | O35: =C35+F35-I35-L35 -> 2 | P35: =D35+G35-J35-M35 -> 5 | Q35: =E35+H35-K35-N35 -> 0
... A42: 3119 | B42: TEKNIK LAINNYA | C42: 0 | D42: 0 | E42: 0 | F42: 0 | G42: 0 | H42: 0 | I42: 0 | J42: 0 | K42: 0 | L42: 0 | M42: 0 | N42: 0 | O42: =C42+F42-I42-L42 -> 0 | P42: =D42+G42-J42-M42 -> 0 | Q42: =E42+H42-K42-N42 -> 0
A43: 3200 | B43: SMK - TEKNOLOGI INFORMASI DAN KOMUNIKASI
A44: 3201 | B44: TEKNIK TELEKOMUNIKASI | C44: 0 | D44: 0 | E44: 2 | F44: 0 | G44: 0 | H44: 0 | I44: 0 | J44: 0 | K44: 0 | L44: 0 | M44: 0 | N44: 0 | O44: =C44+F44-I44-L44 -> 0 | P44: =D44+G44-J44-M44 -> 0 | Q44: =E44+H44-K44-N44 -> 2
A45: 3202 | B45: TEKNIK KOMPUTER DAN INFORMATIKA | C45: 88 | D45: 24 | E45: 18 | F45: 0 | G45: 0 | H45: 0 | I45: 0 | J45: 0 | K45: 0 | L45: 0 | M45: 0 | N45: 0 | O45: =C45+F45-I45-L45 -> 88 | P45: =D45+G45-J45-M45 -> 24 | Q45: =E45+H45-K45-N45 -> 18
A46: 3203 | B46: TEKNIK BROADCASTING | C46: 0 | D46: 0 | E46: 0 | F46: 0 | G46: 0 | H46: 0 | I46: 0 | J46: 0 | K46: 0 | L46: 0 | M46: 0 | N46: 0 | O46: =C46+F46-I46-L46 -> 0 | P46: =D46+G46-J46-M46 -> 0 | Q46: =E46+H46-K46-N46 -> 0
A47: 3300 | B47: SMK - KESEHATAN
...

Sheet ipk.3.8
A1: IPK III/8 : PENEMPATAN PENCARI KERJA MENURUT JENIS ANTAR KERJA TINGKAT PENDIDIKAN PENCARI KERJA,
A2: PENERIMA TENAGA KERJA DAN JENIS KELAMIN
A3: DI KABUPATEN PASER
A4: ='ipk.3.7'!A3 -> PADA TANGGAL : 1 AGUSTUS 2025 s/d 31 AGUSTUS 2025
A6: Kode | B6: I . Tingkat Pendidikan Pencari Kerja yg ditempatkan | C6: Jenis Antar Kerja | L6: Jumlah
C7: AKL | F7: AKAD | I7: AKAN
C8: L | D8: P | E8: JML | F8: L | G8: P | H8: JML | I8: L | J8: P | K8: JML | L8: L | M8: P | N8: JML
A9: 1 | B9: 2 | C9: 3 | D9: 4 | E9: 5 | F9: 6 | G9: 7 | H9: 8 | I9: 9 | J9: 10 | K9: 11 | L9: 12 | M9: 13 | N9: 14
A11: 1 | B11: NON | C11: 0 | D11: 0 | E11: =C11+D11 -> 0 | F11: 0 | G11: 0 | H11: =F11+G11 -> 0 | I11: 0 | J11: 0 | K11: =I11+J11 -> 0 | L11: =C11+F11+I11 -> 0 | M11: =D11+G11+J11 -> 0 | N11: =L11+M11 -> 0
A12: 2 | B12: SD | C12: 0 | D12: 0 | E12: =C12+D12 -> 0 | F12: 0 | G12: 0 | H12: =F12+G12 -> 0 | I12: 0 | J12: 0 | K12: =I12+J12 -> 0 | L12: =C12+F12+I12 -> 0 | M12: =D12+G12+J12 -> 0 | N12: =L12+M12 -> 0
A13: 3 | B13: SLTP | C13: 0 | D13: 0 | E13: =C13+D13 -> 0 | F13: 0 | G13: 0 | H13: =F13+G13 -> 0 | I13: 0 | J13: 0 | K13: =I13+J13 -> 0 | L13: =C13+F13+I13 -> 0 | M13: =D13+G13+J13 -> 0 | N13: =L13+M13 -> 0
A14: 4 | B14: SLTA | C14: 0 | D14: 0 | E14: =C14+D14 -> 0 | F14: 0 | G14: 0 | H14: =F14+G14 -> 0 | I14: 0 | J14: 0 | K14: =I14+J14 -> 0 | L14: =C14+F14+I14 -> 0 | M14: =D14+G14+J14 -> 0 | N14: =L14+M14 -> 0
A15: 5 | B15: DIPLOMA 1 | C15: 0 | D15: 0 | E15: =C15+D15 -> 0 | F15: 0 | G15: 0 | H15: =F15+G15 -> 0 | I15: 0 | J15: 0 | K15: =I15+J15 -> 0 | L15: =C15+F15+I15 -> 0 | M15: =D15+G15+J15 -> 0 | N15: =L15+M15 -> 0
A16: 6 | B16: DIPLOMA 2 | C16: 0 | D16: 0 | E16: =C16+D16 -> 0 | F16: 0 | G16: 0 | H16: =F16+G16 -> 0 | I16: 0 | J16: 0 | K16: =I16+J16 -> 0 | L16: =C16+F16+I16 -> 0 | M16: =D16+G16+J16 -> 0 | N16: =L16+M16 -> 0
A17: 7 | B17: D3/SARJANA MUDA | C17: 0 | D17: 0 | E17: =C17+D17 -> 0 | F17: 0 | G17: 0 | H17: =F17+G17 -> 0 | I17: 0 | J17: 0 | K17: =I17+J17 -> 0 | L17: =C17+F17+I17 -> 0 | M17: =D17+G17+J17 -> 0 | N17: =L17+M17 -> 0
A18: 8 | B18: D4/SARJANA SAINS TERAPAN | C18: 0 | D18: 0 | E18: =C18+D18 -> 0 | F18: 0 | G18: 0 | H18: =F18+G18 -> 0 | I18: 0 | J18: 0 | K18: =I18+J18 -> 0 | L18: =C18+F18+I18 -> 0 | M18: =D18+G18+J18 -> 0 | N18: =L18+M18 -> 0
A19: 9 | B19: AKTA 2 | C19: 0 | D19: 0 | E19: =C19+D19 -> 0 | F19: 0 | G19: 0 | H19: =F19+G19 -> 0 | I19: 0 | J19: 0 | K19: =I19+J19 -> 0 | L19: =C19+F19+I19 -> 0 | M19: =D19+G19+J19 -> 0 | N19: =L19+M19 -> 0
A20: 10 | B20: AKTA 3 | C20: 0 | D20: 0 | E20: =C20+D20 -> 0 | F20: 0 | G20: 0 | H20: =F20+G20 -> 0 | I20: 0 | J20: 0 | K20: =I20+J20 -> 0 | L20: =C20+F20+I20 -> 0 | M20: =D20+G20+J20 -> 0 | N20: =L20+M20 -> 0
A21: 11 | B21: SARJANA | C21: 0 | D21: 0 | E21: =C21+D21 -> 0 | F21: 0 | G21: 0 | H21: =F21+G21 -> 0 | I21: 0 | J21: 0 | K21: =I21+J21 -> 0 | L21: =C21+F21+I21 -> 0 | M21: =D21+G21+J21 -> 0 | N21: =L21+M21 -> 0
A22: 12 | B22: MAGISTER | C22: 0 | D22: 0 | E22: =C22+D22 -> 0 | F22: 0 | G22: 0 | H22: =F22+G22 -> 0 | I22: 0 | J22: 0 | K22: =I22+J22 -> 0 | L22: =C22+F22+I22 -> 0 | M22: =D22+G22+J22 -> 0 | N22: =L22+M22 -> 0
A23: 13 | B23: DOKTORAL | C23: 0 | D23: 0 | E23: =C23+D23 -> 0 | F23: 0 | G23: 0 | H23: =F23+G23 -> 0 | I23: 0 | J23: 0 | K23: =I23+J23 -> 0 | L23: =C23+F23+I23 -> 0 | M23: =D23+G23+J23 -> 0 | N23: =L23+M23 -> 0
B25: JUMLAH | C25: =SUM(C10:C23) -> 0 | D25: =SUM(D10:D23) -> 0 | E25: =SUM(E10:E23) -> 0 | F25: =SUM(F10:F23) -> 0 | G25: =SUM(G10:G23) -> 0 | H25: =SUM(H10:H23) -> 0 | I25: =SUM(I10:I23) -> 0 | J25: =SUM(J10:J23) -> 0 | ... N25: =SUM(N10:N23) -> 0
A27: No | B27: II. Penerima Pencari Kerja | C27: Jenis Antar Kerja | L27: Jumlah
C28: AKL | F28: AKAD | I28: AKAN
C29: L | D29: P | E29: JML | F29: L | G29: P | H29: JML | I29: L | J29: P | K29: JML | L29: L | M29: P | N29: JML
A30: 1 | B30: INSTANSI PEMERINTAH | C30: 0 | D30: 0 | E30: =C30+D30 -> 0 | F30: 0 | G30: 0 | H30: =F30+G30 -> 0 | I30: 0 | J30: 0 | K30: =I30+J30 -> 0 | L30: =C30+F30+I30 -> 0 | M30: =D30+G30+J30 -> 0 | N30: =L30+M30 -> 0
A31: 2 | B31: BUMN/BUMD | C31: 0 | D31: 0 | E31: =C31+D31 -> 0 | F31: 0 | G31: 0 | H31: =F31+G31 -> 0 | I31: 0 | J31: 0 | K31: =I31+J31 -> 0 | L31: =C31+F31+I31 -> 0 | M31: =D31+G31+J31 -> 0 | N31: =L31+M31 -> 0
A32: 3 | B32: KOPERASI | C32: 0 | D32: 0 | E32: =C32+D32 -> 0 | F32: 0 | G32: 0 | H32: =F32+G32 -> 0 | I32: 0 | J32: 0 | K32: =I32+J32 -> 0 | L32: =C32+F32+I32 -> 0 | M32: =D32+G32+J32 -> 0 | N32: =L32+M32 -> 0
A33: 4 | B33: PERUSAHAAN SWASTA | C33: =C25 -> 0 | D33: =D25 -> 0 | E33: =C33+D33 -> 0 | F33: 0 | G33: 0 | H33: =F33+G33 -> 0 | I33: 0 | J33: 0 | K33: =I33+J33 -> 0 | L33: =C33+F33+I33 -> 0 | M33: =D33+G33+J33 -> 0 | N33: =L33+M33 -> 0
A34: 5 | B34: BADAN USAHA LAINNYA | C34: 0 | D34: 0 | E34: =C34+D34 -> 0 | F34: 0 | G34: 0 | H34: =F34+G34 -> 0 | I34: 0 | J34: 0 | K34: =I34+J34 -> 0 | L34: =C34+F34+I34 -> 0 | M34: =D34+G34+J34 -> 0 | N34: =L34+M34 -> 0
A35: 6 | B35: PERORANGAN | C35: 0 | D35: 0 | E35: =C35+D35 -> 0 | F35: 0 | G35: 0 | H35: =F35+G35 -> 0 | I35: 0 | J35: 0 | K35: =I35+J35 -> 0 | L35: =C35+F35+I35 -> 0 | M35: =D35+G35+J35 -> 0 | N35: =L35+M35 -> 0
B37: JUMLAH | C37: =SUM(C30:C35) -> 0 | D37: =SUM(D30:D35) -> 0 | E37: =SUM(E30:E35) -> 0 | F37: =SUM(F30:F35) -> 0 | G37: =SUM(G30:G35) -> 0 | H37: =SUM(H30:H35) -> 0 | I37: =SUM(I30:I35) -> 0 | J37: =SUM(J30:J35) -> 0 | ... N37: =SUM(N30:N35) -> 0
J39: Tana Paser, 2025
J41: Mengetahui :
J42: Kepala Bidang Penempatan
J43: dan Peningkatan Kesempatan Kerja
J47: Agus Setiawan, S.Sos
J48: NIP. 197208162006041007
